{
    DataVersion: 3465,
    size: [15, 10, 15],
    data: [
        {pos: [0, 0, 0], state: "minecraft:cyan_terracotta"},
        {pos: [0, 0, 1], state: "minecraft:cyan_terracotta"},
        {pos: [0, 0, 2], state: "minecraft:cyan_terracotta"},
        {pos: [0, 0, 3], state: "minecraft:cyan_terracotta"},
        {pos: [0, 0, 4], state: "minecraft:cyan_terracotta"},
        {pos: [0, 0, 5], state: "minecraft:cyan_terracotta"},
        {pos: [0, 0, 6], state: "minecraft:cyan_terracotta"},
        {pos: [0, 0, 7], state: "minecraft:cyan_terracotta"},
        {pos: [0, 0, 8], state: "minecraft:cyan_terracotta"},
        {pos: [0, 0, 9], state: "minecraft:cyan_terracotta"},
        {pos: [0, 0, 10], state: "minecraft:cyan_terracotta"},
        {pos: [0, 0, 11], state: "minecraft:cyan_terracotta"},
        {pos: [0, 0, 12], state: "minecraft:cyan_terracotta"},
        {pos: [0, 0, 13], state: "minecraft:cyan_terracotta"},
        {pos: [0, 0, 14], state: "minecraft:cyan_terracotta"},
        {pos: [1, 0, 0], state: "minecraft:cyan_terracotta"},
        {pos: [1, 0, 1], state: "minecraft:cyan_terracotta"},
        {pos: [1, 0, 2], state: "minecraft:cyan_terracotta"},
        {pos: [1, 0, 3], state: "minecraft:cyan_terracotta"},
        {pos: [1, 0, 4], state: "minecraft:cyan_terracotta"},
        {pos: [1, 0, 5], state: "minecraft:cyan_terracotta"},
        {pos: [1, 0, 6], state: "minecraft:cyan_terracotta"},
        {pos: [1, 0, 7], state: "minecraft:cyan_terracotta"},
        {pos: [1, 0, 8], state: "minecraft:cyan_terracotta"},
        {pos: [1, 0, 9], state: "minecraft:cyan_terracotta"},
        {pos: [1, 0, 10], state: "minecraft:cyan_terracotta"},
        {pos: [1, 0, 11], state: "minecraft:cyan_terracotta"},
        {pos: [1, 0, 12], state: "minecraft:cyan_terracotta"},
        {pos: [1, 0, 13], state: "minecraft:cyan_terracotta"},
        {pos: [1, 0, 14], state: "minecraft:cyan_terracotta"},
        {pos: [2, 0, 0], state: "minecraft:cyan_terracotta"},
        {pos: [2, 0, 1], state: "minecraft:cyan_terracotta"},
        {pos: [2, 0, 2], state: "minecraft:cyan_terracotta"},
        {pos: [2, 0, 3], state: "minecraft:cyan_terracotta"},
        {pos: [2, 0, 4], state: "minecraft:cyan_terracotta"},
        {pos: [2, 0, 5], state: "minecraft:cyan_terracotta"},
        {pos: [2, 0, 6], state: "minecraft:cyan_terracotta"},
        {pos: [2, 0, 7], state: "minecraft:cyan_terracotta"},
        {pos: [2, 0, 8], state: "minecraft:cyan_terracotta"},
        {pos: [2, 0, 9], state: "minecraft:cyan_terracotta"},
        {pos: [2, 0, 10], state: "minecraft:cyan_terracotta"},
        {pos: [2, 0, 11], state: "minecraft:cyan_terracotta"},
        {pos: [2, 0, 12], state: "minecraft:cyan_terracotta"},
        {pos: [2, 0, 13], state: "minecraft:cyan_terracotta"},
        {pos: [2, 0, 14], state: "minecraft:cyan_terracotta"},
        {pos: [3, 0, 0], state: "minecraft:cyan_terracotta"},
        {pos: [3, 0, 1], state: "minecraft:cyan_terracotta"},
        {pos: [3, 0, 2], state: "minecraft:cyan_terracotta"},
        {pos: [3, 0, 3], state: "minecraft:cyan_terracotta"},
        {pos: [3, 0, 4], state: "minecraft:cyan_terracotta"},
        {pos: [3, 0, 5], state: "minecraft:cyan_terracotta"},
        {pos: [3, 0, 6], state: "minecraft:cyan_terracotta"},
        {pos: [3, 0, 7], state: "minecraft:cyan_terracotta"},
        {pos: [3, 0, 8], state: "minecraft:cyan_terracotta"},
        {pos: [3, 0, 9], state: "minecraft:cyan_terracotta"},
        {pos: [3, 0, 10], state: "minecraft:cyan_terracotta"},
        {pos: [3, 0, 11], state: "minecraft:cyan_terracotta"},
        {pos: [3, 0, 12], state: "minecraft:cyan_terracotta"},
        {pos: [3, 0, 13], state: "minecraft:cyan_terracotta"},
        {pos: [3, 0, 14], state: "minecraft:cyan_terracotta"},
        {pos: [4, 0, 0], state: "minecraft:cyan_terracotta"},
        {pos: [4, 0, 1], state: "minecraft:cyan_terracotta"},
        {pos: [4, 0, 2], state: "minecraft:grass_block{snowy:false}"},
        {pos: [4, 0, 3], state: "minecraft:grass_block{snowy:false}"},
        {pos: [4, 0, 4], state: "minecraft:grass_block{snowy:false}"},
        {pos: [4, 0, 5], state: "minecraft:cyan_terracotta"},
        {pos: [4, 0, 6], state: "minecraft:cyan_terracotta"},
        {pos: [4, 0, 7], state: "minecraft:cyan_terracotta"},
        {pos: [4, 0, 8], state: "minecraft:cyan_terracotta"},
        {pos: [4, 0, 9], state: "minecraft:cyan_terracotta"},
        {pos: [4, 0, 10], state: "minecraft:cyan_terracotta"},
        {pos: [4, 0, 11], state: "minecraft:cyan_terracotta"},
        {pos: [4, 0, 12], state: "minecraft:cyan_terracotta"},
        {pos: [4, 0, 13], state: "minecraft:cyan_terracotta"},
        {pos: [4, 0, 14], state: "minecraft:cyan_terracotta"},
        {pos: [5, 0, 0], state: "minecraft:cyan_terracotta"},
        {pos: [5, 0, 1], state: "minecraft:cyan_terracotta"},
        {pos: [5, 0, 2], state: "minecraft:grass_block{snowy:false}"},
        {pos: [5, 0, 3], state: "minecraft:dirt"},
        {pos: [5, 0, 4], state: "minecraft:grass_block{snowy:false}"},
        {pos: [5, 0, 5], state: "minecraft:cyan_terracotta"},
        {pos: [5, 0, 6], state: "minecraft:cyan_terracotta"},
        {pos: [5, 0, 7], state: "minecraft:cyan_terracotta"},
        {pos: [5, 0, 8], state: "minecraft:cyan_terracotta"},
        {pos: [5, 0, 9], state: "minecraft:cyan_terracotta"},
        {pos: [5, 0, 10], state: "minecraft:cyan_terracotta"},
        {pos: [5, 0, 11], state: "minecraft:cyan_terracotta"},
        {pos: [5, 0, 12], state: "minecraft:cyan_terracotta"},
        {pos: [5, 0, 13], state: "minecraft:cyan_terracotta"},
        {pos: [5, 0, 14], state: "minecraft:cyan_terracotta"},
        {pos: [6, 0, 0], state: "minecraft:cyan_terracotta"},
        {pos: [6, 0, 1], state: "minecraft:cyan_terracotta"},
        {pos: [6, 0, 2], state: "minecraft:grass_block{snowy:false}"},
        {pos: [6, 0, 3], state: "minecraft:grass_block{snowy:false}"},
        {pos: [6, 0, 4], state: "minecraft:grass_block{snowy:false}"},
        {pos: [6, 0, 5], state: "minecraft:cyan_terracotta"},
        {pos: [6, 0, 6], state: "minecraft:cyan_terracotta"},
        {pos: [6, 0, 7], state: "minecraft:cyan_terracotta"},
        {pos: [6, 0, 8], state: "minecraft:cyan_terracotta"},
        {pos: [6, 0, 9], state: "minecraft:cyan_terracotta"},
        {pos: [6, 0, 10], state: "minecraft:cyan_terracotta"},
        {pos: [6, 0, 11], state: "minecraft:cyan_terracotta"},
        {pos: [6, 0, 12], state: "minecraft:cyan_terracotta"},
        {pos: [6, 0, 13], state: "minecraft:cyan_terracotta"},
        {pos: [6, 0, 14], state: "minecraft:cyan_terracotta"},
        {pos: [7, 0, 0], state: "minecraft:cyan_terracotta"},
        {pos: [7, 0, 1], state: "minecraft:cyan_terracotta"},
        {pos: [7, 0, 2], state: "minecraft:cyan_terracotta"},
        {pos: [7, 0, 3], state: "minecraft:cyan_terracotta"},
        {pos: [7, 0, 4], state: "minecraft:cyan_terracotta"},
        {pos: [7, 0, 5], state: "minecraft:cyan_terracotta"},
        {pos: [7, 0, 6], state: "minecraft:cyan_terracotta"},
        {pos: [7, 0, 7], state: "ae2:creative_energy_cell", nbt: {ForgeCaps: {}, id: "ae2:creative_energy_cell", proxy: {p: 0}}},
        {pos: [7, 0, 8], state: "minecraft:cyan_terracotta"},
        {pos: [7, 0, 9], state: "minecraft:cyan_terracotta"},
        {pos: [7, 0, 10], state: "minecraft:cyan_terracotta"},
        {pos: [7, 0, 11], state: "minecraft:cyan_terracotta"},
        {pos: [7, 0, 12], state: "minecraft:cyan_terracotta"},
        {pos: [7, 0, 13], state: "minecraft:cyan_terracotta"},
        {pos: [7, 0, 14], state: "minecraft:cyan_terracotta"},
        {pos: [8, 0, 0], state: "minecraft:cyan_terracotta"},
        {pos: [8, 0, 1], state: "minecraft:cyan_terracotta"},
        {pos: [8, 0, 2], state: "minecraft:grass_block{snowy:false}"},
        {pos: [8, 0, 3], state: "minecraft:grass_block{snowy:false}"},
        {pos: [8, 0, 4], state: "minecraft:grass_block{snowy:false}"},
        {pos: [8, 0, 5], state: "minecraft:cyan_terracotta"},
        {pos: [8, 0, 6], state: "minecraft:cyan_terracotta"},
        {pos: [8, 0, 7], state: "minecraft:cyan_terracotta"},
        {pos: [8, 0, 8], state: "minecraft:cyan_terracotta"},
        {pos: [8, 0, 9], state: "minecraft:cyan_terracotta"},
        {pos: [8, 0, 10], state: "minecraft:cyan_terracotta"},
        {pos: [8, 0, 11], state: "minecraft:cyan_terracotta"},
        {pos: [8, 0, 12], state: "minecraft:cyan_terracotta"},
        {pos: [8, 0, 13], state: "minecraft:cyan_terracotta"},
        {pos: [8, 0, 14], state: "minecraft:cyan_terracotta"},
        {pos: [9, 0, 0], state: "minecraft:cyan_terracotta"},
        {pos: [9, 0, 1], state: "minecraft:cyan_terracotta"},
        {pos: [9, 0, 2], state: "minecraft:grass_block{snowy:false}"},
        {pos: [9, 0, 3], state: "minecraft:dirt"},
        {pos: [9, 0, 4], state: "minecraft:grass_block{snowy:false}"},
        {pos: [9, 0, 5], state: "minecraft:cyan_terracotta"},
        {pos: [9, 0, 6], state: "minecraft:cyan_terracotta"},
        {pos: [9, 0, 7], state: "minecraft:cyan_terracotta"},
        {pos: [9, 0, 8], state: "minecraft:cyan_terracotta"},
        {pos: [9, 0, 9], state: "minecraft:cyan_terracotta"},
        {pos: [9, 0, 10], state: "minecraft:cyan_terracotta"},
        {pos: [9, 0, 11], state: "minecraft:cyan_terracotta"},
        {pos: [9, 0, 12], state: "minecraft:cyan_terracotta"},
        {pos: [9, 0, 13], state: "minecraft:cyan_terracotta"},
        {pos: [9, 0, 14], state: "minecraft:cyan_terracotta"},
        {pos: [10, 0, 0], state: "minecraft:cyan_terracotta"},
        {pos: [10, 0, 1], state: "minecraft:cyan_terracotta"},
        {pos: [10, 0, 2], state: "minecraft:grass_block{snowy:false}"},
        {pos: [10, 0, 3], state: "minecraft:grass_block{snowy:false}"},
        {pos: [10, 0, 4], state: "minecraft:grass_block{snowy:false}"},
        {pos: [10, 0, 5], state: "minecraft:cyan_terracotta"},
        {pos: [10, 0, 6], state: "minecraft:cyan_terracotta"},
        {pos: [10, 0, 7], state: "minecraft:cyan_terracotta"},
        {pos: [10, 0, 8], state: "minecraft:cyan_terracotta"},
        {pos: [10, 0, 9], state: "minecraft:cyan_terracotta"},
        {pos: [10, 0, 10], state: "minecraft:cyan_terracotta"},
        {pos: [10, 0, 11], state: "minecraft:cyan_terracotta"},
        {pos: [10, 0, 12], state: "minecraft:cyan_terracotta"},
        {pos: [10, 0, 13], state: "minecraft:cyan_terracotta"},
        {pos: [10, 0, 14], state: "minecraft:cyan_terracotta"},
        {pos: [11, 0, 0], state: "minecraft:cyan_terracotta"},
        {pos: [11, 0, 1], state: "minecraft:cyan_terracotta"},
        {pos: [11, 0, 2], state: "minecraft:cyan_terracotta"},
        {pos: [11, 0, 3], state: "minecraft:cyan_terracotta"},
        {pos: [11, 0, 4], state: "minecraft:cyan_terracotta"},
        {pos: [11, 0, 5], state: "minecraft:cyan_terracotta"},
        {pos: [11, 0, 6], state: "minecraft:cyan_terracotta"},
        {pos: [11, 0, 7], state: "minecraft:cyan_terracotta"},
        {pos: [11, 0, 8], state: "minecraft:cyan_terracotta"},
        {pos: [11, 0, 9], state: "minecraft:cyan_terracotta"},
        {pos: [11, 0, 10], state: "minecraft:cyan_terracotta"},
        {pos: [11, 0, 11], state: "minecraft:cyan_terracotta"},
        {pos: [11, 0, 12], state: "minecraft:cyan_terracotta"},
        {pos: [11, 0, 13], state: "minecraft:cyan_terracotta"},
        {pos: [11, 0, 14], state: "minecraft:cyan_terracotta"},
        {pos: [12, 0, 0], state: "minecraft:cyan_terracotta"},
        {pos: [12, 0, 1], state: "minecraft:cyan_terracotta"},
        {pos: [12, 0, 2], state: "minecraft:cyan_terracotta"},
        {pos: [12, 0, 3], state: "minecraft:cyan_terracotta"},
        {pos: [12, 0, 4], state: "minecraft:cyan_terracotta"},
        {pos: [12, 0, 5], state: "minecraft:cyan_terracotta"},
        {pos: [12, 0, 6], state: "minecraft:cyan_terracotta"},
        {pos: [12, 0, 7], state: "minecraft:cyan_terracotta"},
        {pos: [12, 0, 8], state: "minecraft:cyan_terracotta"},
        {pos: [12, 0, 9], state: "minecraft:cyan_terracotta"},
        {pos: [12, 0, 10], state: "minecraft:cyan_terracotta"},
        {pos: [12, 0, 11], state: "minecraft:cyan_terracotta"},
        {pos: [12, 0, 12], state: "minecraft:cyan_terracotta"},
        {pos: [12, 0, 13], state: "minecraft:cyan_terracotta"},
        {pos: [12, 0, 14], state: "minecraft:cyan_terracotta"},
        {pos: [13, 0, 0], state: "minecraft:cyan_terracotta"},
        {pos: [13, 0, 1], state: "minecraft:cyan_terracotta"},
        {pos: [13, 0, 2], state: "minecraft:cyan_terracotta"},
        {pos: [13, 0, 3], state: "minecraft:cyan_terracotta"},
        {pos: [13, 0, 4], state: "minecraft:cyan_terracotta"},
        {pos: [13, 0, 5], state: "minecraft:cyan_terracotta"},
        {pos: [13, 0, 6], state: "minecraft:cyan_terracotta"},
        {pos: [13, 0, 7], state: "minecraft:cyan_terracotta"},
        {pos: [13, 0, 8], state: "minecraft:cyan_terracotta"},
        {pos: [13, 0, 9], state: "minecraft:cyan_terracotta"},
        {pos: [13, 0, 10], state: "minecraft:cyan_terracotta"},
        {pos: [13, 0, 11], state: "minecraft:cyan_terracotta"},
        {pos: [13, 0, 12], state: "minecraft:cyan_terracotta"},
        {pos: [13, 0, 13], state: "minecraft:cyan_terracotta"},
        {pos: [13, 0, 14], state: "minecraft:cyan_terracotta"},
        {pos: [14, 0, 0], state: "minecraft:cyan_terracotta"},
        {pos: [14, 0, 1], state: "minecraft:cyan_terracotta"},
        {pos: [14, 0, 2], state: "minecraft:cyan_terracotta"},
        {pos: [14, 0, 3], state: "minecraft:cyan_terracotta"},
        {pos: [14, 0, 4], state: "minecraft:cyan_terracotta"},
        {pos: [14, 0, 5], state: "minecraft:cyan_terracotta"},
        {pos: [14, 0, 6], state: "minecraft:cyan_terracotta"},
        {pos: [14, 0, 7], state: "minecraft:cyan_terracotta"},
        {pos: [14, 0, 8], state: "minecraft:cyan_terracotta"},
        {pos: [14, 0, 9], state: "minecraft:cyan_terracotta"},
        {pos: [14, 0, 10], state: "minecraft:cyan_terracotta"},
        {pos: [14, 0, 11], state: "minecraft:cyan_terracotta"},
        {pos: [14, 0, 12], state: "minecraft:cyan_terracotta"},
        {pos: [14, 0, 13], state: "minecraft:cyan_terracotta"},
        {pos: [14, 0, 14], state: "minecraft:cyan_terracotta"},
        {pos: [1, 1, 1], state: "minecraft:torch"},
        {pos: [1, 1, 7], state: "minecraft:torch"},
        {pos: [1, 1, 13], state: "minecraft:torch"},
        {pos: [4, 1, 11], state: "rfd:dirt_gen_tier_1{facing:north}", nbt: {id: "rfd:dirt_be_t1", inv: {Items: [{Count: 4b, Slot: 0, id: "minecraft:dirt"}], Size: 1}}},
        {pos: [5, 1, 3], state: "gtceu:rubber_log{axis:y,natural:true}"},
        {pos: [5, 1, 9], state: "minecraft:gray_concrete"},
        {pos: [5, 1, 10], state: "minecraft:gray_concrete"},
        {pos: [5, 1, 11], state: "minecraft:gray_concrete"},
        {pos: [6, 1, 10], state: "simple_resource_generators:raw_conversion_generator{facing:north}", nbt: {ForgeCaps: {}, Items: [{Count: 1b, Slot: 0b, id: "gtceu:raw_coal"}], id: "simple_resource_generators:raw_conversion_generator"}},
        {pos: [6, 1, 11], state: "minecraft:gray_concrete"},
        {pos: [7, 1, 1], state: "minecraft:torch"},
        {pos: [7, 1, 7], state: "ae2:drive{facing:north,spin:0}", nbt: {ForgeCaps: {}, id: "ae2:drive", inv: {item0: {Count: 1b, id: "ae2:item_storage_cell_64k", tag: {}}, item1: {Count: 1b, id: "ae2:item_storage_cell_64k", tag: {}}, item2: {Count: 1b, id: "ae2:item_storage_cell_64k", tag: {}}, item3: {Count: 1b, id: "ae2:item_storage_cell_64k", tag: {}}, item4: {Count: 1b, id: "ae2:item_storage_cell_64k", tag: {}}, item5: {Count: 1b, id: "ae2:item_storage_cell_64k", tag: {}}, item6: {Count: 1b, id: "ae2:item_storage_cell_64k", tag: {}}, item7: {Count: 1b, id: "ae2:item_storage_cell_64k", tag: {}}, item8: {Count: 1b, id: "ae2:fluid_storage_cell_64k", tag: {}}, item9: {Count: 1b, id: "ae2:fluid_storage_cell_64k", tag: {}}}, priority: 0, proxy: {p: 0}}},
        {pos: [7, 1, 10], state: "simple_resource_generators:simple_lava_condenser{facing:north}", nbt: {ForgeCaps: {}, Items: [], fluidTank: {Amount: 0, FluidName: "minecraft:empty"}, id: "simple_resource_generators:simple_lava_condenser"}},
        {pos: [7, 1, 11], state: "minecraft:gray_concrete"},
        {pos: [7, 1, 13], state: "minecraft:torch"},
        {pos: [8, 1, 10], state: "simple_resource_generators:random_ore_block_generator_placement{facing:north}"},
        {pos: [8, 1, 11], state: "minecraft:gray_concrete"},
        {pos: [9, 1, 3], state: "gtceu:rubber_log{axis:y,natural:true}"},
        {pos: [9, 1, 9], state: "minecraft:gray_concrete"},
        {pos: [9, 1, 10], state: "minecraft:gray_concrete"},
        {pos: [9, 1, 11], state: "minecraft:gray_concrete"},
        {pos: [10, 1, 11], state: "cobblefordays:tier_1", nbt: {ForgeCaps: {}, count: 0, id: "cobblefordays:tier_1", timer: 10}},
        {pos: [13, 1, 1], state: "minecraft:torch"},
        {pos: [13, 1, 7], state: "minecraft:torch"},
        {pos: [13, 1, 13], state: "minecraft:torch"},
        {pos: [4, 2, 11], state: "gtceu:lv_super_chest{facing:north,server_tick:false}", nbt: {ForgeCaps: {}, allowInputFromOutputSideItems: 0b, autoOutputItems: 0b, cache: {isDistinct: 0b, storage: {Items: [{Count: 14b, Slot: 0, id: "minecraft:dirt"}], Size: 1}}, cover: {}, id: "gtceu:lv_super_chest", isVoiding: 0b, itemsStoredInside: 0, lockedItem: {Items: [], Size: 1}, outputFacingItems: "south", paintingColor: -1, stored: {Count: 1b, id: "minecraft:dirt"}, storedAmount: 14}},
        {pos: [5, 2, 3], state: "gtceu:rubber_log{axis:y,natural:true}"},
        {pos: [5, 2, 9], state: "minecraft:gray_concrete"},
        {pos: [5, 2, 10], state: "minecraft:gray_concrete"},
        {pos: [5, 2, 11], state: "minecraft:gray_concrete"},
        {pos: [6, 2, 10], state: "gtceu:gravel_coal_ore"},
        {pos: [6, 2, 11], state: "minecraft:gray_concrete"},
        {pos: [7, 2, 7], state: "ae2:cable_bus{light_level:9,waterlogged:false}", nbt: {ForgeCaps: {}, cable: {gn: {p: 0}, id: "ae2:fluix_glass_cable"}, hasRedstone: 2, id: "ae2:cable_bus", north: {filter_type: "ALL", gn: {p: 0}, id: "ae2:crafting_terminal", sort_by: "NAME", sort_direction: "ASCENDING", spin: 0b, view_mode: "ALL"}}},
        {pos: [7, 2, 10], state: "simple_resource_generators:simple_water_condenser{facing:north}", nbt: {ForgeCaps: {}, Items: [], fluidTank: {Amount: 0, FluidName: "minecraft:empty"}, id: "simple_resource_generators:simple_water_condenser"}},
        {pos: [7, 2, 11], state: "minecraft:gray_concrete"},
        {pos: [8, 2, 3], state: "gtceu:rubber_log{axis:y,natural:true}"},
        {pos: [8, 2, 10], state: "gtceu:coal_ore"},
        {pos: [8, 2, 11], state: "minecraft:gray_concrete"},
        {pos: [9, 2, 3], state: "gtceu:rubber_log{axis:y,natural:true}"},
        {pos: [9, 2, 9], state: "minecraft:gray_concrete"},
        {pos: [9, 2, 10], state: "minecraft:gray_concrete"},
        {pos: [9, 2, 11], state: "minecraft:gray_concrete"},
        {pos: [10, 2, 11], state: "gtceu:lv_super_chest{facing:north,server_tick:false}", nbt: {ForgeCaps: {}, allowInputFromOutputSideItems: 0b, autoOutputItems: 0b, cache: {isDistinct: 0b, storage: {Items: [{Count: 44b, Slot: 0, id: "minecraft:cobblestone"}], Size: 1}}, cover: {}, id: "gtceu:lv_super_chest", isVoiding: 0b, itemsStoredInside: 0, lockedItem: {Items: [], Size: 1}, outputFacingItems: "south", paintingColor: -1, stored: {Count: 1b, id: "minecraft:cobblestone"}, storedAmount: 44}},
        {pos: [4, 3, 3], state: "gtceu:rubber_leaves{distance:1,persistent:false,waterlogged:false}"},
        {pos: [5, 3, 1], state: "gtceu:rubber_leaves{distance:2,persistent:false,waterlogged:false}"},
        {pos: [5, 3, 2], state: "gtceu:rubber_leaves{distance:1,persistent:false,waterlogged:false}"},
        {pos: [5, 3, 3], state: "gtceu:rubber_log{axis:y,natural:true}"},
        {pos: [5, 3, 4], state: "gtceu:rubber_leaves{distance:1,persistent:false,waterlogged:false}"},
        {pos: [5, 3, 5], state: "gtceu:rubber_leaves{distance:2,persistent:false,waterlogged:false}"},
        {pos: [5, 3, 9], state: "minecraft:gray_concrete"},
        {pos: [5, 3, 10], state: "minecraft:gray_concrete"},
        {pos: [5, 3, 11], state: "minecraft:gray_concrete"},
        {pos: [6, 3, 1], state: "gtceu:rubber_leaves{distance:3,persistent:false,waterlogged:false}"},
        {pos: [6, 3, 2], state: "gtceu:rubber_leaves{distance:2,persistent:false,waterlogged:false}"},
        {pos: [6, 3, 3], state: "gtceu:rubber_leaves{distance:1,persistent:false,waterlogged:false}"},
        {pos: [6, 3, 4], state: "gtceu:rubber_leaves{distance:2,persistent:false,waterlogged:false}"},
        {pos: [6, 3, 5], state: "gtceu:rubber_leaves{distance:3,persistent:false,waterlogged:false}"},
        {pos: [6, 3, 9], state: "minecraft:gray_concrete"},
        {pos: [6, 3, 10], state: "minecraft:gray_concrete"},
        {pos: [6, 3, 11], state: "minecraft:gray_concrete"},
        {pos: [7, 3, 0], state: "gtceu:rubber_leaves{distance:3,persistent:false,waterlogged:false}"},
        {pos: [7, 3, 1], state: "gtceu:rubber_leaves{distance:2,persistent:false,waterlogged:false}"},
        {pos: [7, 3, 2], state: "gtceu:rubber_leaves{distance:1,persistent:false,waterlogged:false}"},
        {pos: [7, 3, 3], state: "gtceu:rubber_log{axis:y,natural:true}"},
        {pos: [7, 3, 4], state: "gtceu:rubber_leaves{distance:1,persistent:false,waterlogged:false}"},
        {pos: [7, 3, 5], state: "gtceu:rubber_leaves{distance:2,persistent:false,waterlogged:false}"},
        {pos: [7, 3, 6], state: "gtceu:rubber_leaves{distance:3,persistent:false,waterlogged:false}"},
        {pos: [7, 3, 9], state: "minecraft:gray_concrete"},
        {pos: [7, 3, 10], state: "minecraft:gray_concrete"},
        {pos: [7, 3, 11], state: "minecraft:gray_concrete"},
        {pos: [8, 3, 1], state: "gtceu:rubber_leaves{distance:3,persistent:false,waterlogged:false}"},
        {pos: [8, 3, 2], state: "gtceu:rubber_leaves{distance:2,persistent:false,waterlogged:false}"},
        {pos: [8, 3, 3], state: "gtceu:rubber_leaves{distance:1,persistent:false,waterlogged:false}"},
        {pos: [8, 3, 4], state: "gtceu:rubber_leaves{distance:2,persistent:false,waterlogged:false}"},
        {pos: [8, 3, 5], state: "gtceu:rubber_leaves{distance:3,persistent:false,waterlogged:false}"},
        {pos: [8, 3, 9], state: "minecraft:gray_concrete"},
        {pos: [8, 3, 10], state: "minecraft:gray_concrete"},
        {pos: [8, 3, 11], state: "minecraft:gray_concrete"},
        {pos: [9, 3, 1], state: "gtceu:rubber_leaves{distance:2,persistent:false,waterlogged:false}"},
        {pos: [9, 3, 2], state: "gtceu:rubber_leaves{distance:1,persistent:false,waterlogged:false}"},
        {pos: [9, 3, 3], state: "gtceu:rubber_log{axis:y,natural:true}"},
        {pos: [9, 3, 4], state: "gtceu:rubber_leaves{distance:1,persistent:false,waterlogged:false}"},
        {pos: [9, 3, 5], state: "gtceu:rubber_leaves{distance:2,persistent:false,waterlogged:false}"},
        {pos: [9, 3, 9], state: "minecraft:gray_concrete"},
        {pos: [9, 3, 10], state: "minecraft:gray_concrete"},
        {pos: [9, 3, 11], state: "minecraft:gray_concrete"},
        {pos: [10, 3, 3], state: "gtceu:rubber_leaves{distance:1,persistent:false,waterlogged:false}"},
        {pos: [1, 4, 3], state: "gtceu:rubber_leaves{distance:3,persistent:false,waterlogged:false}"},
        {pos: [2, 4, 1], state: "gtceu:rubber_leaves{distance:4,persistent:false,waterlogged:false}"},
        {pos: [2, 4, 2], state: "gtceu:rubber_leaves{distance:3,persistent:false,waterlogged:false}"},
        {pos: [2, 4, 3], state: "gtceu:rubber_leaves{distance:2,persistent:false,waterlogged:false}"},
        {pos: [2, 4, 4], state: "gtceu:rubber_leaves{distance:3,persistent:false,waterlogged:false}"},
        {pos: [2, 4, 5], state: "gtceu:rubber_leaves{distance:4,persistent:false,waterlogged:false}"},
        {pos: [3, 4, 1], state: "gtceu:rubber_leaves{distance:3,persistent:false,waterlogged:false}"},
        {pos: [3, 4, 2], state: "gtceu:rubber_leaves{distance:2,persistent:false,waterlogged:false}"},
        {pos: [3, 4, 3], state: "gtceu:rubber_leaves{distance:1,persistent:false,waterlogged:false}"},
        {pos: [3, 4, 4], state: "gtceu:rubber_leaves{distance:2,persistent:false,waterlogged:false}"},
        {pos: [3, 4, 5], state: "gtceu:rubber_leaves{distance:3,persistent:false,waterlogged:false}"},
        {pos: [4, 4, 0], state: "gtceu:rubber_leaves{distance:3,persistent:false,waterlogged:false}"},
        {pos: [4, 4, 1], state: "gtceu:rubber_leaves{distance:2,persistent:false,waterlogged:false}"},
        {pos: [4, 4, 2], state: "gtceu:rubber_leaves{distance:1,persistent:false,waterlogged:false}"},
        {pos: [4, 4, 3], state: "gtceu:rubber_log{axis:y,natural:true}"},
        {pos: [4, 4, 4], state: "gtceu:rubber_leaves{distance:1,persistent:false,waterlogged:false}"},
        {pos: [4, 4, 5], state: "gtceu:rubber_leaves{distance:2,persistent:false,waterlogged:false}"},
        {pos: [4, 4, 6], state: "gtceu:rubber_leaves{distance:3,persistent:false,waterlogged:false}"},
        {pos: [5, 4, 1], state: "gtceu:rubber_leaves{distance:2,persistent:false,waterlogged:false}"},
        {pos: [5, 4, 2], state: "gtceu:rubber_leaves{distance:1,persistent:false,waterlogged:false}"},
        {pos: [5, 4, 3], state: "gtceu:rubber_log{axis:y,natural:true}"},
        {pos: [5, 4, 4], state: "gtceu:rubber_leaves{distance:1,persistent:false,waterlogged:false}"},
        {pos: [5, 4, 5], state: "gtceu:rubber_leaves{distance:2,persistent:false,waterlogged:false}"},
        {pos: [6, 4, 1], state: "gtceu:rubber_leaves{distance:3,persistent:false,waterlogged:false}"},
        {pos: [6, 4, 2], state: "gtceu:rubber_leaves{distance:2,persistent:false,waterlogged:false}"},
        {pos: [6, 4, 3], state: "gtceu:rubber_leaves{distance:1,persistent:false,waterlogged:false}"},
        {pos: [6, 4, 4], state: "gtceu:rubber_leaves{distance:2,persistent:false,waterlogged:false}"},
        {pos: [6, 4, 5], state: "gtceu:rubber_leaves{distance:3,persistent:false,waterlogged:false}"},
        {pos: [7, 4, 1], state: "gtceu:rubber_leaves{distance:3,persistent:false,waterlogged:false}"},
        {pos: [7, 4, 2], state: "gtceu:rubber_leaves{distance:2,persistent:false,waterlogged:false}"},
        {pos: [7, 4, 3], state: "gtceu:rubber_leaves{distance:1,persistent:false,waterlogged:false}"},
        {pos: [7, 4, 4], state: "gtceu:rubber_leaves{distance:2,persistent:false,waterlogged:false}"},
        {pos: [7, 4, 5], state: "gtceu:rubber_leaves{distance:3,persistent:false,waterlogged:false}"},
        {pos: [7, 4, 10], state: "angelblockrenewed:angel_block"},
        {pos: [8, 4, 2], state: "gtceu:rubber_leaves{distance:3,persistent:false,waterlogged:false}"},
        {pos: [8, 4, 3], state: "gtceu:rubber_leaves{distance:2,persistent:false,waterlogged:false}"},
        {pos: [8, 4, 4], state: "gtceu:rubber_leaves{distance:3,persistent:false,waterlogged:false}"},
        {pos: [9, 4, 3], state: "gtceu:rubber_leaves{distance:1,persistent:false,waterlogged:false}"},
        {pos: [10, 4, 3], state: "gtceu:rubber_log{axis:y,natural:true}"},
        {pos: [2, 5, 3], state: "gtceu:rubber_leaves{distance:3,persistent:false,waterlogged:false}"},
        {pos: [3, 5, 2], state: "gtceu:rubber_leaves{distance:3,persistent:false,waterlogged:false}"},
        {pos: [3, 5, 3], state: "gtceu:rubber_leaves{distance:2,persistent:false,waterlogged:false}"},
        {pos: [3, 5, 4], state: "gtceu:rubber_leaves{distance:3,persistent:false,waterlogged:false}"},
        {pos: [4, 5, 1], state: "gtceu:rubber_leaves{distance:3,persistent:false,waterlogged:false}"},
        {pos: [4, 5, 2], state: "gtceu:rubber_leaves{distance:2,persistent:false,waterlogged:false}"},
        {pos: [4, 5, 3], state: "gtceu:rubber_leaves{distance:1,persistent:false,waterlogged:false}"},
        {pos: [4, 5, 4], state: "gtceu:rubber_leaves{distance:2,persistent:false,waterlogged:false}"},
        {pos: [4, 5, 5], state: "gtceu:rubber_leaves{distance:3,persistent:false,waterlogged:false}"},
        {pos: [5, 5, 2], state: "gtceu:rubber_leaves{distance:1,persistent:false,waterlogged:false}"},
        {pos: [5, 5, 3], state: "gtceu:rubber_log{axis:y,natural:true}"},
        {pos: [5, 5, 4], state: "gtceu:rubber_leaves{distance:1,persistent:false,waterlogged:false}"},
        {pos: [5, 5, 5], state: "gtceu:rubber_leaves{distance:2,persistent:false,waterlogged:false}"},
        {pos: [5, 5, 6], state: "gtceu:rubber_leaves{distance:3,persistent:false,waterlogged:false}"},
        {pos: [5, 5, 7], state: "gtceu:rubber_leaves{distance:4,persistent:false,waterlogged:false}"},
        {pos: [6, 5, 0], state: "gtceu:rubber_leaves{distance:4,persistent:false,waterlogged:false}"},
        {pos: [6, 5, 2], state: "gtceu:rubber_leaves{distance:2,persistent:false,waterlogged:false}"},
        {pos: [6, 5, 3], state: "gtceu:rubber_leaves{distance:1,persistent:false,waterlogged:false}"},
        {pos: [6, 5, 4], state: "gtceu:rubber_leaves{distance:2,persistent:false,waterlogged:false}"},
        {pos: [6, 5, 5], state: "gtceu:rubber_leaves{distance:3,persistent:false,waterlogged:false}"},
        {pos: [6, 5, 6], state: "gtceu:rubber_leaves{distance:4,persistent:false,waterlogged:false}"},
        {pos: [6, 5, 7], state: "gtceu:rubber_leaves{distance:5,persistent:false,waterlogged:false}"},
        {pos: [6, 5, 8], state: "gtceu:rubber_leaves{distance:6,persistent:false,waterlogged:false}"},
        {pos: [7, 5, 0], state: "gtceu:rubber_leaves{distance:5,persistent:false,waterlogged:false}"},
        {pos: [7, 5, 1], state: "gtceu:rubber_leaves{distance:4,persistent:false,waterlogged:false}"},
        {pos: [7, 5, 2], state: "gtceu:rubber_leaves{distance:3,persistent:false,waterlogged:false}"},
        {pos: [7, 5, 3], state: "gtceu:rubber_leaves{distance:2,persistent:false,waterlogged:false}"},
        {pos: [7, 5, 4], state: "gtceu:rubber_leaves{distance:3,persistent:false,waterlogged:false}"},
        {pos: [7, 5, 5], state: "gtceu:rubber_leaves{distance:4,persistent:false,waterlogged:false}"},
        {pos: [7, 5, 6], state: "gtceu:rubber_leaves{distance:5,persistent:false,waterlogged:false}"},
        {pos: [7, 5, 7], state: "gtceu:rubber_leaves{distance:6,persistent:false,waterlogged:false}"},
        {pos: [7, 5, 10], state: "minecraft:torch"},
        {pos: [8, 5, 0], state: "gtceu:rubber_leaves{distance:5,persistent:false,waterlogged:false}"},
        {pos: [8, 5, 1], state: "gtceu:rubber_leaves{distance:4,persistent:false,waterlogged:false}"},
        {pos: [8, 5, 2], state: "gtceu:rubber_leaves{distance:3,persistent:false,waterlogged:false}"},
        {pos: [8, 5, 3], state: "gtceu:rubber_leaves{distance:2,persistent:false,waterlogged:false}"},
        {pos: [8, 5, 4], state: "gtceu:rubber_leaves{distance:3,persistent:false,waterlogged:false}"},
        {pos: [8, 5, 5], state: "gtceu:rubber_leaves{distance:4,persistent:false,waterlogged:false}"},
        {pos: [8, 5, 6], state: "gtceu:rubber_leaves{distance:5,persistent:false,waterlogged:false}"},
        {pos: [9, 5, 1], state: "gtceu:rubber_leaves{distance:3,persistent:false,waterlogged:false}"},
        {pos: [9, 5, 2], state: "gtceu:rubber_leaves{distance:2,persistent:false,waterlogged:false}"},
        {pos: [9, 5, 3], state: "gtceu:rubber_leaves{distance:1,persistent:false,waterlogged:false}"},
        {pos: [9, 5, 5], state: "gtceu:rubber_leaves{distance:5,persistent:false,waterlogged:false}"},
        {pos: [10, 5, 2], state: "gtceu:rubber_leaves{distance:1,persistent:false,waterlogged:false}"},
        {pos: [10, 5, 3], state: "gtceu:rubber_log{axis:y,natural:true}"},
        {pos: [10, 5, 4], state: "gtceu:rubber_leaves{distance:1,persistent:false,waterlogged:false}"},
        {pos: [11, 5, 3], state: "gtceu:rubber_leaves{distance:1,persistent:false,waterlogged:false}"},
        {pos: [2, 6, 3], state: "gtceu:rubber_leaves{distance:4,persistent:false,waterlogged:false}"},
        {pos: [3, 6, 1], state: "gtceu:rubber_leaves{distance:5,persistent:false,waterlogged:false}"},
        {pos: [3, 6, 2], state: "gtceu:rubber_leaves{distance:4,persistent:false,waterlogged:false}"},
        {pos: [3, 6, 3], state: "gtceu:rubber_leaves{distance:3,persistent:false,waterlogged:false}"},
        {pos: [3, 6, 4], state: "gtceu:rubber_leaves{distance:4,persistent:false,waterlogged:false}"},
        {pos: [3, 6, 5], state: "gtceu:rubber_leaves{distance:5,persistent:false,waterlogged:false}"},
        {pos: [4, 6, 0], state: "gtceu:rubber_leaves{distance:5,persistent:false,waterlogged:false}"},
        {pos: [4, 6, 1], state: "gtceu:rubber_leaves{distance:4,persistent:false,waterlogged:false}"},
        {pos: [4, 6, 2], state: "gtceu:rubber_leaves{distance:3,persistent:false,waterlogged:false}"},
        {pos: [4, 6, 3], state: "gtceu:rubber_leaves{distance:2,persistent:false,waterlogged:false}"},
        {pos: [4, 6, 4], state: "gtceu:rubber_leaves{distance:3,persistent:false,waterlogged:false}"},
        {pos: [4, 6, 5], state: "gtceu:rubber_leaves{distance:4,persistent:false,waterlogged:false}"},
        {pos: [4, 6, 6], state: "gtceu:rubber_leaves{distance:5,persistent:false,waterlogged:false}"},
        {pos: [5, 6, 0], state: "gtceu:rubber_leaves{distance:4,persistent:false,waterlogged:false}"},
        {pos: [5, 6, 1], state: "gtceu:rubber_leaves{distance:3,persistent:false,waterlogged:false}"},
        {pos: [5, 6, 2], state: "gtceu:rubber_leaves{distance:2,persistent:false,waterlogged:false}"},
        {pos: [5, 6, 3], state: "gtceu:rubber_leaves{distance:1,persistent:false,waterlogged:false}"},
        {pos: [5, 6, 4], state: "gtceu:rubber_leaves{distance:2,persistent:false,waterlogged:false}"},
        {pos: [5, 6, 5], state: "gtceu:rubber_leaves{distance:3,persistent:false,waterlogged:false}"},
        {pos: [5, 6, 6], state: "gtceu:rubber_leaves{distance:4,persistent:false,waterlogged:false}"},
        {pos: [6, 6, 0], state: "gtceu:rubber_leaves{distance:3,persistent:false,waterlogged:false}"},
        {pos: [6, 6, 1], state: "gtceu:rubber_leaves{distance:2,persistent:false,waterlogged:false}"},
        {pos: [6, 6, 2], state: "gtceu:rubber_leaves{distance:1,persistent:false,waterlogged:false}"},
        {pos: [6, 6, 3], state: "gtceu:rubber_log{axis:y,natural:true}"},
        {pos: [6, 6, 4], state: "gtceu:rubber_leaves{distance:1,persistent:false,waterlogged:false}"},
        {pos: [6, 6, 5], state: "gtceu:rubber_leaves{distance:2,persistent:false,waterlogged:false}"},
        {pos: [6, 6, 6], state: "gtceu:rubber_leaves{distance:3,persistent:false,waterlogged:false}"},
        {pos: [6, 6, 7], state: "gtceu:rubber_leaves{distance:4,persistent:false,waterlogged:false}"},
        {pos: [7, 6, 0], state: "gtceu:rubber_leaves{distance:4,persistent:false,waterlogged:false}"},
        {pos: [7, 6, 1], state: "gtceu:rubber_leaves{distance:3,persistent:false,waterlogged:false}"},
        {pos: [7, 6, 2], state: "gtceu:rubber_leaves{distance:2,persistent:false,waterlogged:false}"},
        {pos: [7, 6, 3], state: "gtceu:rubber_leaves{distance:1,persistent:false,waterlogged:false}"},
        {pos: [7, 6, 4], state: "gtceu:rubber_leaves{distance:2,persistent:false,waterlogged:false}"},
        {pos: [7, 6, 5], state: "gtceu:rubber_leaves{distance:3,persistent:false,waterlogged:false}"},
        {pos: [7, 6, 6], state: "gtceu:rubber_leaves{distance:4,persistent:false,waterlogged:false}"},
        {pos: [7, 6, 7], state: "gtceu:rubber_leaves{distance:5,persistent:false,waterlogged:false}"},
        {pos: [7, 6, 8], state: "gtceu:rubber_leaves{distance:6,persistent:false,waterlogged:false}"},
        {pos: [8, 6, 0], state: "gtceu:rubber_leaves{distance:5,persistent:false,waterlogged:false}"},
        {pos: [8, 6, 1], state: "gtceu:rubber_leaves{distance:4,persistent:false,waterlogged:false}"},
        {pos: [8, 6, 2], state: "gtceu:rubber_leaves{distance:3,persistent:false,waterlogged:false}"},
        {pos: [8, 6, 3], state: "gtceu:rubber_leaves{distance:2,persistent:false,waterlogged:false}"},
        {pos: [8, 6, 4], state: "gtceu:rubber_leaves{distance:3,persistent:false,waterlogged:false}"},
        {pos: [8, 6, 5], state: "gtceu:rubber_leaves{distance:4,persistent:false,waterlogged:false}"},
        {pos: [8, 6, 6], state: "gtceu:rubber_leaves{distance:5,persistent:false,waterlogged:false}"},
        {pos: [8, 6, 7], state: "gtceu:rubber_leaves{distance:6,persistent:false,waterlogged:false}"},
        {pos: [9, 6, 0], state: "gtceu:rubber_leaves{distance:4,persistent:false,waterlogged:false}"},
        {pos: [9, 6, 1], state: "gtceu:rubber_leaves{distance:3,persistent:false,waterlogged:false}"},
        {pos: [9, 6, 2], state: "gtceu:rubber_leaves{distance:2,persistent:false,waterlogged:false}"},
        {pos: [9, 6, 3], state: "gtceu:rubber_leaves{distance:1,persistent:false,waterlogged:false}"},
        {pos: [9, 6, 4], state: "gtceu:rubber_leaves{distance:2,persistent:false,waterlogged:false}"},
        {pos: [9, 6, 6], state: "gtceu:rubber_leaves{distance:5,persistent:false,waterlogged:false}"},
        {pos: [10, 6, 1], state: "gtceu:rubber_leaves{distance:2,persistent:false,waterlogged:false}"},
        {pos: [10, 6, 2], state: "gtceu:rubber_leaves{distance:1,persistent:false,waterlogged:false}"},
        {pos: [10, 6, 3], state: "gtceu:rubber_log{axis:y,natural:true}"},
        {pos: [10, 6, 4], state: "gtceu:rubber_leaves{distance:1,persistent:false,waterlogged:false}"},
        {pos: [10, 6, 5], state: "gtceu:rubber_leaves{distance:2,persistent:false,waterlogged:false}"},
        {pos: [11, 6, 2], state: "gtceu:rubber_leaves{distance:2,persistent:false,waterlogged:false}"},
        {pos: [11, 6, 3], state: "gtceu:rubber_leaves{distance:1,persistent:false,waterlogged:false}"},
        {pos: [11, 6, 4], state: "gtceu:rubber_leaves{distance:2,persistent:false,waterlogged:false}"},
        {pos: [12, 6, 3], state: "gtceu:rubber_leaves{distance:2,persistent:false,waterlogged:false}"},
        {pos: [3, 7, 3], state: "gtceu:rubber_leaves{distance:4,persistent:false,waterlogged:false}"},
        {pos: [4, 7, 1], state: "gtceu:rubber_leaves{distance:5,persistent:false,waterlogged:false}"},
        {pos: [4, 7, 2], state: "gtceu:rubber_leaves{distance:4,persistent:false,waterlogged:false}"},
        {pos: [4, 7, 3], state: "gtceu:rubber_leaves{distance:3,persistent:false,waterlogged:false}"},
        {pos: [4, 7, 4], state: "gtceu:rubber_leaves{distance:4,persistent:false,waterlogged:false}"},
        {pos: [4, 7, 5], state: "gtceu:rubber_leaves{distance:5,persistent:false,waterlogged:false}"},
        {pos: [5, 7, 1], state: "gtceu:rubber_leaves{distance:4,persistent:false,waterlogged:false}"},
        {pos: [5, 7, 2], state: "gtceu:rubber_leaves{distance:3,persistent:false,waterlogged:false}"},
        {pos: [5, 7, 3], state: "gtceu:rubber_leaves{distance:2,persistent:false,waterlogged:false}"},
        {pos: [5, 7, 4], state: "gtceu:rubber_leaves{distance:3,persistent:false,waterlogged:false}"},
        {pos: [5, 7, 5], state: "gtceu:rubber_leaves{distance:4,persistent:false,waterlogged:false}"},
        {pos: [6, 7, 0], state: "gtceu:rubber_leaves{distance:4,persistent:false,waterlogged:false}"},
        {pos: [6, 7, 1], state: "gtceu:rubber_leaves{distance:3,persistent:false,waterlogged:false}"},
        {pos: [6, 7, 2], state: "gtceu:rubber_leaves{distance:2,persistent:false,waterlogged:false}"},
        {pos: [6, 7, 3], state: "gtceu:rubber_leaves{distance:1,persistent:false,waterlogged:false}"},
        {pos: [6, 7, 4], state: "gtceu:rubber_leaves{distance:2,persistent:false,waterlogged:false}"},
        {pos: [6, 7, 5], state: "gtceu:rubber_leaves{distance:3,persistent:false,waterlogged:false}"},
        {pos: [6, 7, 6], state: "gtceu:rubber_leaves{distance:4,persistent:false,waterlogged:false}"},
        {pos: [7, 7, 1], state: "gtceu:rubber_leaves{distance:4,persistent:false,waterlogged:false}"},
        {pos: [7, 7, 2], state: "gtceu:rubber_leaves{distance:3,persistent:false,waterlogged:false}"},
        {pos: [7, 7, 3], state: "gtceu:rubber_leaves{distance:2,persistent:false,waterlogged:false}"},
        {pos: [7, 7, 4], state: "gtceu:rubber_leaves{distance:3,persistent:false,waterlogged:false}"},
        {pos: [7, 7, 5], state: "gtceu:rubber_leaves{distance:4,persistent:false,waterlogged:false}"},
        {pos: [7, 7, 6], state: "gtceu:rubber_leaves{distance:5,persistent:false,waterlogged:false}"},
        {pos: [7, 7, 7], state: "gtceu:rubber_leaves{distance:6,persistent:false,waterlogged:false}"},
        {pos: [8, 7, 0], state: "gtceu:rubber_leaves{distance:5,persistent:false,waterlogged:false}"},
        {pos: [8, 7, 1], state: "gtceu:rubber_leaves{distance:4,persistent:false,waterlogged:false}"},
        {pos: [8, 7, 2], state: "gtceu:rubber_leaves{distance:3,persistent:false,waterlogged:false}"},
        {pos: [8, 7, 3], state: "gtceu:rubber_leaves{distance:2,persistent:false,waterlogged:false}"},
        {pos: [8, 7, 4], state: "gtceu:rubber_leaves{distance:3,persistent:false,waterlogged:false}"},
        {pos: [8, 7, 5], state: "gtceu:rubber_leaves{distance:4,persistent:false,waterlogged:false}"},
        {pos: [8, 7, 6], state: "gtceu:rubber_leaves{distance:5,persistent:false,waterlogged:false}"},
        {pos: [9, 7, 0], state: "gtceu:rubber_leaves{distance:4,persistent:false,waterlogged:false}"},
        {pos: [9, 7, 1], state: "gtceu:rubber_leaves{distance:3,persistent:false,waterlogged:false}"},
        {pos: [9, 7, 2], state: "gtceu:rubber_leaves{distance:2,persistent:false,waterlogged:false}"},
        {pos: [9, 7, 3], state: "gtceu:rubber_leaves{distance:1,persistent:false,waterlogged:false}"},
        {pos: [9, 7, 4], state: "gtceu:rubber_leaves{distance:2,persistent:false,waterlogged:false}"},
        {pos: [9, 7, 5], state: "gtceu:rubber_leaves{distance:3,persistent:false,waterlogged:false}"},
        {pos: [9, 7, 6], state: "gtceu:rubber_leaves{distance:4,persistent:false,waterlogged:false}"},
        {pos: [10, 7, 0], state: "gtceu:rubber_leaves{distance:3,persistent:false,waterlogged:false}"},
        {pos: [10, 7, 1], state: "gtceu:rubber_leaves{distance:2,persistent:false,waterlogged:false}"},
        {pos: [10, 7, 2], state: "gtceu:rubber_leaves{distance:1,persistent:false,waterlogged:false}"},
        {pos: [10, 7, 3], state: "gtceu:rubber_log{axis:y,natural:true}"},
        {pos: [10, 7, 4], state: "gtceu:rubber_leaves{distance:1,persistent:false,waterlogged:false}"},
        {pos: [10, 7, 5], state: "gtceu:rubber_leaves{distance:2,persistent:false,waterlogged:false}"},
        {pos: [10, 7, 6], state: "gtceu:rubber_leaves{distance:3,persistent:false,waterlogged:false}"},
        {pos: [10, 7, 7], state: "gtceu:rubber_leaves{distance:4,persistent:false,waterlogged:false}"},
        {pos: [11, 7, 0], state: "gtceu:rubber_leaves{distance:4,persistent:false,waterlogged:false}"},
        {pos: [11, 7, 1], state: "gtceu:rubber_leaves{distance:3,persistent:false,waterlogged:false}"},
        {pos: [11, 7, 2], state: "gtceu:rubber_leaves{distance:2,persistent:false,waterlogged:false}"},
        {pos: [11, 7, 3], state: "gtceu:rubber_leaves{distance:1,persistent:false,waterlogged:false}"},
        {pos: [11, 7, 4], state: "gtceu:rubber_leaves{distance:2,persistent:false,waterlogged:false}"},
        {pos: [11, 7, 5], state: "gtceu:rubber_leaves{distance:3,persistent:false,waterlogged:false}"},
        {pos: [11, 7, 6], state: "gtceu:rubber_leaves{distance:4,persistent:false,waterlogged:false}"},
        {pos: [12, 7, 0], state: "gtceu:rubber_leaves{distance:5,persistent:false,waterlogged:false}"},
        {pos: [12, 7, 1], state: "gtceu:rubber_leaves{distance:4,persistent:false,waterlogged:false}"},
        {pos: [12, 7, 2], state: "gtceu:rubber_leaves{distance:3,persistent:false,waterlogged:false}"},
        {pos: [12, 7, 3], state: "gtceu:rubber_leaves{distance:2,persistent:false,waterlogged:false}"},
        {pos: [12, 7, 4], state: "gtceu:rubber_leaves{distance:3,persistent:false,waterlogged:false}"},
        {pos: [12, 7, 5], state: "gtceu:rubber_leaves{distance:4,persistent:false,waterlogged:false}"},
        {pos: [12, 7, 6], state: "gtceu:rubber_leaves{distance:5,persistent:false,waterlogged:false}"},
        {pos: [13, 7, 1], state: "gtceu:rubber_leaves{distance:5,persistent:false,waterlogged:false}"},
        {pos: [13, 7, 2], state: "gtceu:rubber_leaves{distance:4,persistent:false,waterlogged:false}"},
        {pos: [13, 7, 3], state: "gtceu:rubber_leaves{distance:3,persistent:false,waterlogged:false}"},
        {pos: [13, 7, 4], state: "gtceu:rubber_leaves{distance:4,persistent:false,waterlogged:false}"},
        {pos: [13, 7, 5], state: "gtceu:rubber_leaves{distance:5,persistent:false,waterlogged:false}"},
        {pos: [14, 7, 3], state: "gtceu:rubber_leaves{distance:4,persistent:false,waterlogged:false}"},
        {pos: [4, 8, 3], state: "gtceu:rubber_leaves{distance:4,persistent:false,waterlogged:false}"},
        {pos: [5, 8, 2], state: "gtceu:rubber_leaves{distance:4,persistent:false,waterlogged:false}"},
        {pos: [5, 8, 3], state: "gtceu:rubber_leaves{distance:3,persistent:false,waterlogged:false}"},
        {pos: [5, 8, 4], state: "gtceu:rubber_leaves{distance:4,persistent:false,waterlogged:false}"},
        {pos: [6, 8, 1], state: "gtceu:rubber_leaves{distance:4,persistent:false,waterlogged:false}"},
        {pos: [6, 8, 2], state: "gtceu:rubber_leaves{distance:3,persistent:false,waterlogged:false}"},
        {pos: [6, 8, 3], state: "gtceu:rubber_leaves{distance:2,persistent:false,waterlogged:false}"},
        {pos: [6, 8, 4], state: "gtceu:rubber_leaves{distance:3,persistent:false,waterlogged:false}"},
        {pos: [6, 8, 5], state: "gtceu:rubber_leaves{distance:4,persistent:false,waterlogged:false}"},
        {pos: [7, 8, 2], state: "gtceu:rubber_leaves{distance:4,persistent:false,waterlogged:false}"},
        {pos: [7, 8, 3], state: "gtceu:rubber_leaves{distance:3,persistent:false,waterlogged:false}"},
        {pos: [7, 8, 4], state: "gtceu:rubber_leaves{distance:4,persistent:false,waterlogged:false}"},
        {pos: [8, 8, 1], state: "gtceu:rubber_leaves{distance:5,persistent:false,waterlogged:false}"},
        {pos: [8, 8, 2], state: "gtceu:rubber_leaves{distance:4,persistent:false,waterlogged:false}"},
        {pos: [8, 8, 3], state: "gtceu:rubber_leaves{distance:3,persistent:false,waterlogged:false}"},
        {pos: [8, 8, 4], state: "gtceu:rubber_leaves{distance:4,persistent:false,waterlogged:false}"},
        {pos: [8, 8, 5], state: "gtceu:rubber_leaves{distance:5,persistent:false,waterlogged:false}"},
        {pos: [9, 8, 1], state: "gtceu:rubber_leaves{distance:4,persistent:false,waterlogged:false}"},
        {pos: [9, 8, 2], state: "gtceu:rubber_leaves{distance:3,persistent:false,waterlogged:false}"},
        {pos: [9, 8, 3], state: "gtceu:rubber_leaves{distance:2,persistent:false,waterlogged:false}"},
        {pos: [9, 8, 4], state: "gtceu:rubber_leaves{distance:3,persistent:false,waterlogged:false}"},
        {pos: [9, 8, 5], state: "gtceu:rubber_leaves{distance:4,persistent:false,waterlogged:false}"},
        {pos: [10, 8, 0], state: "gtceu:rubber_leaves{distance:4,persistent:false,waterlogged:false}"},
        {pos: [10, 8, 1], state: "gtceu:rubber_leaves{distance:3,persistent:false,waterlogged:false}"},
        {pos: [10, 8, 2], state: "gtceu:rubber_leaves{distance:2,persistent:false,waterlogged:false}"},
        {pos: [10, 8, 3], state: "gtceu:rubber_leaves{distance:1,persistent:false,waterlogged:false}"},
        {pos: [10, 8, 4], state: "gtceu:rubber_leaves{distance:2,persistent:false,waterlogged:false}"},
        {pos: [10, 8, 5], state: "gtceu:rubber_leaves{distance:3,persistent:false,waterlogged:false}"},
        {pos: [10, 8, 6], state: "gtceu:rubber_leaves{distance:4,persistent:false,waterlogged:false}"},
        {pos: [11, 8, 1], state: "gtceu:rubber_leaves{distance:4,persistent:false,waterlogged:false}"},
        {pos: [11, 8, 2], state: "gtceu:rubber_leaves{distance:3,persistent:false,waterlogged:false}"},
        {pos: [11, 8, 3], state: "gtceu:rubber_leaves{distance:2,persistent:false,waterlogged:false}"},
        {pos: [11, 8, 4], state: "gtceu:rubber_leaves{distance:3,persistent:false,waterlogged:false}"},
        {pos: [11, 8, 5], state: "gtceu:rubber_leaves{distance:4,persistent:false,waterlogged:false}"},
        {pos: [12, 8, 1], state: "gtceu:rubber_leaves{distance:5,persistent:false,waterlogged:false}"},
        {pos: [12, 8, 2], state: "gtceu:rubber_leaves{distance:4,persistent:false,waterlogged:false}"},
        {pos: [12, 8, 3], state: "gtceu:rubber_leaves{distance:3,persistent:false,waterlogged:false}"},
        {pos: [12, 8, 4], state: "gtceu:rubber_leaves{distance:4,persistent:false,waterlogged:false}"},
        {pos: [12, 8, 5], state: "gtceu:rubber_leaves{distance:5,persistent:false,waterlogged:false}"},
        {pos: [13, 8, 3], state: "gtceu:rubber_leaves{distance:4,persistent:false,waterlogged:false}"},
        {pos: [8, 9, 3], state: "gtceu:rubber_leaves{distance:4,persistent:false,waterlogged:false}"},
        {pos: [9, 9, 2], state: "gtceu:rubber_leaves{distance:4,persistent:false,waterlogged:false}"},
        {pos: [9, 9, 3], state: "gtceu:rubber_leaves{distance:3,persistent:false,waterlogged:false}"},
        {pos: [9, 9, 4], state: "gtceu:rubber_leaves{distance:4,persistent:false,waterlogged:false}"},
        {pos: [10, 9, 1], state: "gtceu:rubber_leaves{distance:4,persistent:false,waterlogged:false}"},
        {pos: [10, 9, 2], state: "gtceu:rubber_leaves{distance:3,persistent:false,waterlogged:false}"},
        {pos: [10, 9, 3], state: "gtceu:rubber_leaves{distance:2,persistent:false,waterlogged:false}"},
        {pos: [10, 9, 4], state: "gtceu:rubber_leaves{distance:3,persistent:false,waterlogged:false}"},
        {pos: [10, 9, 5], state: "gtceu:rubber_leaves{distance:4,persistent:false,waterlogged:false}"},
        {pos: [11, 9, 2], state: "gtceu:rubber_leaves{distance:4,persistent:false,waterlogged:false}"},
        {pos: [11, 9, 3], state: "gtceu:rubber_leaves{distance:3,persistent:false,waterlogged:false}"},
        {pos: [11, 9, 4], state: "gtceu:rubber_leaves{distance:4,persistent:false,waterlogged:false}"},
        {pos: [12, 9, 3], state: "gtceu:rubber_leaves{distance:4,persistent:false,waterlogged:false}"}
    ],
    entities: [
        {blockPos: [7, 1, 9], pos: [7.5d, 1.03125d, 9.5d], nbt: {Air: 300s, BalmData: {}, CanUpdate: 1b, Facing: 1b, FallDistance: 0.0f, Fire: -1s, Fixed: 0b, Invisible: 0b, Invulnerable: 0b, Item: {Count: 1b, id: "ex_hammers:netherite_hammer", tag: {Damage: 0}}, ItemDropChance: 1.0f, ItemRotation: 4b, Motion: [0.0d, 0.0d, 0.0d], OnGround: 0b, PortalCooldown: 0, Pos: [7.5d, 65.03125d, 9.5d], Rotation: [0.0f, -90.0f], TileX: 7, TileY: 65, TileZ: 9, UUID: [I; 1869378298, -544585551, -1677245361, -1121995990], id: "minecraft:glow_item_frame"}}
    ],
    palette: [
        "minecraft:cyan_terracotta",
        "minecraft:grass_block{snowy:false}",
        "minecraft:dirt",
        "gtceu:rubber_log{axis:y,natural:true}",
        "minecraft:gray_concrete",
        "simple_resource_generators:random_ore_block_generator_placement{facing:north}",
        "gtceu:gravel_coal_ore",
        "gtceu:coal_ore",
        "gtceu:rubber_leaves{distance:1,persistent:false,waterlogged:false}",
        "gtceu:rubber_leaves{distance:2,persistent:false,waterlogged:false}",
        "gtceu:rubber_leaves{distance:3,persistent:false,waterlogged:false}",
        "gtceu:rubber_leaves{distance:4,persistent:false,waterlogged:false}",
        "angelblockrenewed:angel_block",
        "gtceu:rubber_leaves{distance:5,persistent:false,waterlogged:false}",
        "gtceu:rubber_leaves{distance:6,persistent:false,waterlogged:false}",
        "minecraft:torch",
        "ae2:creative_energy_cell",
        "rfd:dirt_gen_tier_1{facing:north}",
        "simple_resource_generators:raw_conversion_generator{facing:north}",
        "ae2:drive{facing:north,spin:0}",
        "simple_resource_generators:simple_lava_condenser{facing:north}",
        "cobblefordays:tier_1",
        "gtceu:lv_super_chest{facing:north,server_tick:false}",
        "ae2:cable_bus{light_level:9,waterlogged:false}",
        "simple_resource_generators:simple_water_condenser{facing:north}"
    ]
}